Workbook

Sheet Cover
B2: ANALYSIS OF SURPLUS – LEARNING MODEL
B3: SA1 Health & Care Actuarial – Chapter 20
B5: Sheet | C5: Description | D5: Tab Name
B6: COVER | C6: Navigation & Overview | D6: Cover
B7: ASSUMP | C7: Valuation Basis Assumptions | D7: Assumptions
B8: BS | C8: Opening & Closing Balance Sheets | D8: BalanceSheet
B9: AoS | C9: Analysis of Surplus (Main Model) | D9: AoS_Main
B10: WORKED EG | C10: Numerical Worked Example | D10: WorkedExample
B11: EV | C11: Analysis of Change in EV | D11: AoEV
B12: PMI | C12: Short-Term Profit Analysis (PMI) | D12: PMI_Profit
B14: COLOUR CODING GUIDE
B15: Blue text | C15: Hardcoded INPUT – change to run scenarios
B16: Black text | C16: Calculated FORMULA – do not overwrite
B17: Green text | C17: Cross-sheet LINK
B18: Yellow bg | C18: Key assumption cell – review carefully

Sheet Assumptions
B1: VALUATION BASIS ASSUMPTIONS
B3: A. ECONOMIC ASSUMPTIONS
B4: Assumption | C4: Start of Year | D4: End of Year | E4: Notes
B5: Discount rate (% pa) | C5: 0.005 | D5: 0.005 | E5: Risk-free rate proxy
B6: Expected investment return (% pa) | C6: 0.025 | D6: 0.025 | E6: Internal view on assets
B7: Risk-free rate (% pa) | C7: 0.005 | D7: 0.005 | E7: Solvency II basis
B8: Matching adjustment (% pa) | C8: 0.003 | D8: 0.003 | E8: Fundamental spread deducted
B9: Inflation rate (% pa) | C9: 0.02 | D9: 0.02 | E9: RPI / Medical inflation
B10: Actual investment return (% pa) | C10: 0.045 | D10: 0.045 | E10: Drives investment variance
B12: B. NON-ECONOMIC (INSURANCE) ASSUMPTIONS
B13: Assumption | C13: Expected | D13: Actual | E13: Variance Impact
B14: Morbidity rate (% of exposed) | C14: 0.05 | D14: 0.055 | E14: =D14-C14 -> 0.005
B15: Mortality rate (% of exposed) | C15: 0.01 | D15: 0.009 | E15: =D15-C15 -> -0.001
B16: Lapse / persistency rate (%) | C16: 0.08 | D16: 0.09 | E16: =D16-C16 -> 0.01
B17: Expense per policy (£) | C17: 120 | D17: 135 | E17: =D17-C17 -> 15
B18: Claims incurred (£000s) | C18: 5000 | D18: 5350 | E18: =D18-C18 -> 350
B21: C. NEW BUSINESS VOLUME
B22: Item | C22: Value | D22: Unit | E22: Notes
B23: New policies written | C23: 500 | D23: No. of policies | E23: During analysis year
B24: Average premium (£) | C24: 1200 | D24: £ per policy | E24: Initial annual premium
B25: Initial expenses (£) | C25: 350 | D25: £ per policy | E25: Acquisition cost
B26: Reserve per new policy(£) | C26: 800 | D26: £ per policy | E26: Opening supervisory reserve

Sheet BalanceSheet
B1: SUPERVISORY BALANCE SHEET
B3: Item | C3: Start of Year (£) | D3: End of Year (£) | E3: Change (£)
B4: ASSETS
B5: Fixed interest bonds | C5: 120000 | D5: 121500 | E5: =D5-C5 -> 1500
B6: Equities | C6: 40000 | D6: 43200 | E6: =D6-C6 -> 3200
B7: Cash & money market | C7: 20000 | D7: 20900 | E7: =D7-C7 -> 900
B8: Property | C8: 10000 | D8: 10200 | E8: =D8-C8 -> 200
B9: Other assets | C9: 1000 | D9: 1050 | E9: =D9-C9 -> 50
B10: TOTAL ASSETS | C10: =SUM(C5:C9) -> 191000 | D10: =SUM(D5:D9) -> 196850 | E10: =D10-C10 -> 5850
B12: LIABILITIES (TECHNICAL PROVISIONS)
B13: Best Estimate Liability (BEL) | C13: 155000 | D13: 158500 | E13: =D13-C13 -> 3500
B14: Risk Margin | C14: 8000 | D14: 8200 | E14: =D14-C14 -> 200
B15: Other technical provisions | C15: 2000 | D15: 2100 | E15: =D15-C15 -> 100
B16: Other liabilities | C16: 3000 | D16: 3200 | E16: =D16-C16 -> 200
B17: TOTAL LIABILITIES | C17: =SUM(C13:C16) -> 168000 | D17: =SUM(D13:D16) -> 172000 | E17: =D17-C17 -> 4000
B19: SUPERVISORY SURPLUS
B20: Surplus – Start of Year | C20: =C10-C17 -> 23000
B21: Surplus – End of Year | D21: =D10-D17 -> 24850
B22: Surplus ARISING over year | E22: =D21-C20 -> 1850
B24: SOLVENCY CAPITAL REQUIREMENT (SCR)
B25: SCR (Pillar 1 capital requirement) | C25: 25000 | D25: 26000 | E25: =D25-C25 -> 1000
B26: MCR (Minimum capital requirement) | C26: 7500 | D26: 7800 | E26: =D26-C26 -> 300
B27: Free surplus (Surplus over SCR) | C27: =C20-C25 -> -2000 | D27: =D21-D25 -> -1150 | E27: =D27-C27 -> 850

Sheet AoS_Main
B1: ANALYSIS OF SUPERVISORY VALUATION SURPLUS
B2: Reconciles opening surplus to closing surplus • Blue cells = inputs • Change assumptions to explore variances
B4: Item | C4: Amount (£) | D4: Running Total (£)
B5: OPENING SURPLUS (Start of Year) | C5: =BalanceSheet!C20 -> 23000 | D5: =C5 -> 23000
B7: 1. OPENING ADJUSTMENTS
B8: Model / data / methodology corrections | C8: 0
B9: Other opening adjustments | C9: 0
B10: Total Opening Adjustments | C10: =SUM(C8:C9) -> 0 | D10: =C5+C10 -> 23000
B12: 2. RETURN ON OPENING SURPLUS
B13: Expected return on opening surplus | C13: =C5*Assumptions!C5 -> 115
B14: Excess of actual over expected return (on surplus assets) | C14: 0
B15: Total Return on Opening Surplus | C15: =SUM(C13:C14) -> 115 | D15: =D10+C15 -> 23115
B17: 3. ECONOMIC VARIANCES
B18: Investment return variance | C18: =BalanceSheet!C10*(Assumptions!C6-Assumptions!C5) -> 3820
B19: Inflation variance | C19: 0
B20: Changes in economic assumptions | C20: 0
B21: Asset mix / matching adjustment variance | C21: 0
B22: Mismatch profit / (loss) | C22: 0
B23: Total Economic Variances | C23: =SUM(C18:C22) -> 3820 | D23: =D15+C23 -> 26935
B25: 4. NON-ECONOMIC (INSURANCE) VARIANCES
B26: Morbidity / claim incidence variance | C26: -50000
B27: Mortality variance | C27: 15000
B28: Persistency / lapse rate variance | C28: -25000
B29: Expense variance | C29: -30000
B30: One-off / exceptional expenses | C30: 0
B31: Changes in non-economic assumptions | C31: 0
B32: Total Non-Economic Variances | C32: =SUM(C26:C31) -> -90000 | D32: =D23+C32 -> -63065
B34: 5. NEW BUSINESS IMPACT
B35: New business contribution | C35: 12000
B36: Total New Business | C36: =C35 -> 12000 | D36: =D32+C36 -> -51065
B38: 6. OTHER VARIANCES
B39: Capital injected / (distributed) | C39: 0
B40: Tax changes | C40: 0
B41: Exceptional / one-off items | C41: 0
B42: Total Other Variances | C42: =SUM(C39:C41) -> 0 | D42: =D36+C42 -> -51065
B44: 7. UNEXPLAINED MOVEMENT
B45: Unexplained residual (difference to actual closing surplus) | C45: =BalanceSheet!D21-D42 -> 75915 | D45: =D42+C45 -> 24850
B47: CLOSING SURPLUS (End of Year) – per Analysis | C47: =D42+C45 -> 24850 | D47: =D45 -> 24850
B48: CLOSING SURPLUS (End of Year) – per Balance Sheet | C48: =BalanceSheet!D21 -> 24850
B49: RECONCILIATION CHECK (must be zero) | C49: =C48-C47 -> 0
...

Sheet WorkedExample
B1: WORKED EXAMPLE – SA1 Ch.20 Numerical Question
B2: Liability: pay 100 in 2 years | Expense 5 in 6m | Expense 10 in 18m | Assets = 200
B4: VALUATION BASIS INPUTS
B5: Parameter | C5: Value | D5: Notes
B6: Discount rate (% pa) | C6: 0.005 | D6: Both SOY and EOY valuations
B7: Assets at start of year | C7: 200 | D7: Total invested assets
B8: Expense – 6 months (SOY basis) | C8: 5 | D8: Outgo at t=0.5
B9: Expense – 18 months (SOY basis) | C9: 10 | D9: Outgo at t=1.5 (SOY)
B10: Benefit payable – 2 years | C10: 100 | D10: Outgo at t=2
B11: Actual investment return (% pa) | C11: 0.045 | D11: Achieved during the year
B12: Actual expense incurred | C12: 15 | D12: Incurred at t=0.5 (mid-year)
B13: Expense – 6 months (EOY basis) | C13: 10 | D13: Outgo at t=0.5 on EOY valuation
B16: PART (i) – SURPLUS AT START OF YEAR
B17: Component | C17: Formula Used | D17: Value
B18: v = 1/(1+i) | C18: =1/(1+C6) -> 0.99502488 | D18: =1/(1+C6) -> 0.99502488
B19: PV of benefit (100·v²) | C19: =C10*(1/(1+C6))^2 -> 99.00745 | D19: =C10*(1/(1+C6))^2 -> 99.00745
B20: PV of exp at 6m (5·v^0.5) | C20: =C8*(1/(1+C6))^0.5 -> 4.9875467 | D20: =C8*(1/(1+C6))^0.5 -> 4.9875467
B21: PV of exp at 18m (10·v^1.5) | C21: =C9*(1/(1+C6))^1.5 -> 9.925466 | D21: =C9*(1/(1+C6))^1.5 -> 9.925466
B22: Total Liability (SOY) | C22: =D19+D20+D21 -> 113.92046 | D22: =D19+D20+D21 -> 113.92046
B23: Assets (SOY) | C23: =C7 -> 200 | D23: =C7 -> 200
B24: SURPLUS – Start of Year | C24: =D23-D22 -> 86.079537 | D24: =D23-D22 -> 86.079537
B27: PART (ii) – SURPLUS AT END OF YEAR & SURPLUS ARISING
B28: Assets EOY (200·(1+act_ret) – 15·(1+act_ret)^0.5) | C28: =C7*(1+C11)-C12*(1+C11)^0.5 -> 193.66621 | D28: =C7*(1+C11)-C12*(1+C11)^0.5 -> 193.66621
B29: v (EOY) = same discount rate | C29: =1/(1+C6) -> 0.99502488 | D29: =1/(1+C6) -> 0.99502488
B30: PV of benefit at EOY (100·v) | C30: =C10*(1/(1+C6)) -> 99.502488 | D30: =C10*(1/(1+C6)) -> 99.502488
B31: PV of exp at 6m EOY (10·v^0.5) | C31: =C13*(1/(1+C6))^0.5 -> 9.9750934 | D31: =C13*(1/(1+C6))^0.5 -> 9.9750934
B32: Total Liability (EOY) | C32: =D30+D31 -> 109.47758 | D32: =D30+D31 -> 109.47758
B33: SURPLUS – End of Year | C33: =D28-D32 -> 84.188633 | D33: =D28-D32 -> 84.188633
B34: SURPLUS ARISING (EOY – SOY) | C34: =D33-D24 -> -1.8909041 | D34: =D33-D24 -> -1.8909041
B37: PART (iii) – ANALYSIS OF SURPLUS ARISING
B38: Source | C38: Workings | D38: Surplus (£)
B39: (a) Expected return on opening surplus | C39: SOY surplus × discount rate | D39: =D24*C6 -> 0.43039768
B40: (b) Investment return variance | C40: Assets at actual return minus assets at expected return (expenses at actual) | D40: =C7*(1+C11)^1-C12*(1+C11)^0.5 - (C7*(1+C6)^1-C12*(1+C6)^0.5) -> 7.703667
B41: …alternative: assets × (act_ret – exp_ret) | C41: Simplified: ignores expense timing | D41: =C7*(C11-C6) -> 8
B42: (c) Expense variance | C42: Expected expense assets minus actual expense assets (both at expected ret) | D42: =(C7*(1+C6)-C8*(1+C6)^0.5) - (C7*(1+C6)-C12*(1+C6)^0.5) -> 10.024969
B43: …alternative: (exp – act) × (1+i)^0.5 | C43: Simpler: expected less actual, accrued to year end | D43: =(C8-C12)*(1+C6)^0.5 -> -10.024969
B44: TOTAL (should equal surplus arising) | C44: Check: matches D34 | D44: =D39+D41+D43 -> -1.5945711
B45: ✓ CHECK (must = 0) | C45: Must be zero | D45: =D44-D34 -> 0.29633298

Sheet AoEV
B1: ANALYSIS OF CHANGE IN EMBEDDED VALUE (EV)
B2: EV = Free Surplus + Required Capital (net of CoHRC) + PVIF | Typically 1-year analysis
B4: EV COMPONENTS
B5: Component | C5: Start of Year (£) | D5: End of Year (£)
B6: Free surplus | C6: 20000 | D6: 21500
B7: Required capital | C7: 30000 | D7: 31000
B8: Less: Cost of holding req. cap | C8: -2000 | D8: -2100
B9: Present Value of In-Force (PVIF) | C9: 55000 | D9: 57000
B10: TOTAL EV – Start of Year | C10: =SUM(C6:C9) -> 103000
B11: TOTAL EV – End of Year | D11: =SUM(D6:D9) -> 107400
B13: ANALYSIS OF CHANGE IN EMBEDDED VALUE
B14: Item | C14: Amount (£) | D14: Cumulative (£)
B15: OPENING EV | C15: =C10 -> 103000 | D15: =C15 -> 103000
B16: 1. Return on net assets (expected) | C16: =C10*0.005 -> 515 | D16: =D15+C16 -> 103515
B17: Return on net assets (excess actual) | C17: 0 | D17: =D16+C17 -> 103515
B18: 2. Expected return on in-force (PVIF unwind) | C18: =C9*0.005 -> 275 | D18: =D17+C18 -> 103790
B19: 3. Experience variances – Economic | C19: 0 | D19: =D18+C19 -> 103790
B20: Experience variances – Non-economic | C20: 0 | D20: =D19+C20 -> 103790
B21: 4. Operating assumption changes | C21: 0 | D21: =D20+C21 -> 103790
B22: 5. New business contribution | C22: 0 | D22: =D21+C22 -> 103790
B23: 6. Other items (dividends, capinj, tax) | C23: 0 | D23: =D22+C23 -> 103790
B24: 7. Unexplained | C24: =D23-C10 -> 790 | D24: =D23+C24 -> 104580
B25: CLOSING EV (formula) | C25: =D24 -> 104580 | D25: =D24 -> 104580
B26: CLOSING EV (per schedule) | C26: =D11 -> 107400 | D26: =D11 -> 107400
B27: CHECK (must = 0) | C27: =C26-C25 -> 2820 | D27: =C27 -> 2820
B30: PVIF UNWIND FORMULA (Ch.20 Section 6.1)
B31: PVIF(t+1) - PVIF(t) = PVIF(t) × r - S(t) where: r = discount rate used in PVIF projection S(t) = expected surplus (profit) arising in period starting at t Interpretation: PVIF grows at discount rate ('unwind'), but falls by the expected surplus that emerges into net assets. Overall EV is unchanged when experience is exactly as expected – value just moves from PVIF → net assets.

Sheet PMI_Profit
B1: PMI SHORT-TERM PROFIT ANALYSIS (SA1 Ch.20 Section 7)
B2: Three key indices: Rate of Incidence | Avg Cost per Claim | Loss Ratio | Analysed by cohort & quarter
B4: COHORT DATA INPUTS – INDIVIDUAL PMI
B5: Item | C5: Q1 | D5: Q2 | E5: Q3 | F5: Q4
B6: Policies exposed to risk | C6: 10000 | D6: 10200 | E6: 10100 | F6: 10050
B7: Claims incurred (£000s) | C7: 1800 | D7: 1950 | E7: 1870 | F7: 1820
B8: Of which: paid to date | C8: 1500 | D8: 1600 | E8: 1530 | F8: 1480
B9: Outstanding (OS) reported | C9: 200 | D9: 230 | E9: 210 | F9: 200
B10: IBNR provision | C10: 100 | D10: 120 | E10: 130 | F10: 140
B11: Earned premium (£000s) | C11: 3000 | D11: 3100 | E11: 3080 | F11: 3050
B12: Separate claims count | C12: 520 | D12: 560 | E12: 540 | F12: 530
B13: Pricing assumption – loss ratio | C13: 0.6 | D13: 0.6 | E13: 0.6 | F13: 0.6
B14: Pricing assumption – incidence | C14: 0.052 | D14: 0.052 | E14: 0.052 | F14: 0.052
B15: Pricing assumption – avg cost(£) | C15: 3462 | D15: 3462 | E15: 3462 | F15: 3462
B18: CALCULATED INDICES – ACTUAL vs PRICING ASSUMPTION
B19: Index | C19: Q1 | D19: Q2 | E19: Q3 | F19: Q4
B20: Rate of Incidence (actual) | C20: =C12/C6 -> 0.052 | D20: =D12/D6 -> 0.054901961 | E20: =E12/E6 -> 0.053465347 | F20: =F12/F6 -> 0.052736318
B21: Rate of Incidence (pricing) | C21: =C14 -> 0.052 | D21: =D14 -> 0.052 | E21: =E14 -> 0.052 | F21: =F14 -> 0.052
B22: Incidence variance (act – pricing) | C22: =C20-C21 -> 0 | D22: =D20-D21 -> 0.0029019608 | E22: =E20-E21 -> 0.0014653465 | F22: =F20-F21 -> 0.00073631841
B23: Average cost per claim £ (actual) | C23: =C7*1000/C12 -> 3461.5385 | D23: =D7*1000/D12 -> 3482.1429 | E23: =E7*1000/E12 -> 3462.963 | F23: =F7*1000/F12 -> 3433.9623
B24: Avg cost – pricing assumption £ | C24: =C15 -> 3462 | D24: =D15 -> 3462 | E24: =E15 -> 3462 | F24: =F15 -> 3462
B25: Avg cost variance (act – pricing £) | C25: =C23-C24 -> -0.46153846 | D25: =D23-D24 -> 20.142857 | E25: =E23-E24 -> 0.96296296 | F25: =F23-F24 -> -28.037736
B26: Loss ratio (actual) | C26: =C7/C11 -> 0.6 | D26: =D7/D11 -> 0.62903226 | E26: =E7/E11 -> 0.60714286 | F26: =F7/F11 -> 0.59672131
B27: Loss ratio (pricing assumption) | C27: =C13 -> 0.6 | D27: =D13 -> 0.6 | E27: =E13 -> 0.6 | F27: =F13 -> 0.6
B28: Loss ratio variance (act – pricing) | C28: =C26-C27 -> 0 | D28: =D26-D27 -> 0.029032258 | E28: =E26-E27 -> 0.0071428571 | F28: =F26-F27 -> -0.0032786885
B31: KEY DEFINITIONS (Ch.20 §7)
B32: Rate of incidence = No. of separate claims ÷ Lives exposed to risk
B33: Average cost per claim = Total incurred claims ÷ No. of separate claims
B34: Loss ratio = Total incurred claims ÷ Earned premium
B35: Incurred claims = Paid to date + Outstanding (OS) + IBNR
B36: Consistency in claim definition is vital for meaningful trend analysis and inter-company comparison
B37: NCD systems require rapid cohort experience assessment to adjust promotion/demotion rules
B38: Duration-based cohorts used for PMI (selection effect in early policy years → lower loss ratios)
