Workbook

Sheet Assumptions
A1: GALAXY PROMISE SIGNATURE — LEVEL PREMIUM PRICING MODEL
A2: Policyholder: Male, Age 40 | Sum Insured: ₹25,00,000 | Illustrative / Dummy Values
A3: A. POLICY & POLICYHOLDER PARAMETERS
A4: Entry age (years) | B4: 40 | C4: Dummy — edit freely
A5: Maximum lock-in age (years) | B5: 55 | C5: Dummy — edit freely
A6: Sum Insured (₹) | B6: 2500000 | C6: Dummy — edit freely
A7: Policy currency discount rate (p.a.) | B7: 0.07 | C7: Dummy — edit freely
A8: Medical inflation rate (p.a.) | B8: 0.08 | C8: Dummy — edit freely
A9: Expense loading (% of pure premium) | B9: 0.2 | C9: Dummy — edit freely
A10: Profit margin (% of gross premium) | B10: 0.1 | C10: Dummy — edit freely
A11: B. BASE CLAIM COST PARAMETERS (Age 40)
A12: Base annual claim frequency (per policy) | B12: 0.12 | C12: Dummy — edit freely
A13: Base average claim severity (₹) | B13: 85000 | C13: Dummy — edit freely
A14: Base pure premium = freq × severity (₹) | B14: =B12*B13 -> 10200 | C14: Calculated
A16: C. AGE-MORBIDITY RELATIVITIES (index: age 40 = 1.00)
A17: These factors scale the base pure premium upward as the policyholder ages. Source: Illustrative.
A18: Age | B18: Morbidity Factor | C18: Note
A19: 40 | B19: 1 | C19: Dummy — actuarial table
A20: 41 | B20: 1.05 | C20: Dummy — actuarial table
A21: 42 | B21: 1.1 | C21: Dummy — actuarial table
A22: 43 | B22: 1.16 | C22: Dummy — actuarial table
A23: 44 | B23: 1.22 | C23: Dummy — actuarial table
A24: 45 | B24: 1.29 | C24: Dummy — actuarial table
A25: 46 | B25: 1.37 | C25: Dummy — actuarial table
A26: 47 | B26: 1.45 | C26: Dummy — actuarial table
A27: 48 | B27: 1.54 | C27: Dummy — actuarial table
A28: 49 | B28: 1.63 | C28: Dummy — actuarial table
A29: 50 | B29: 1.73 | C29: Dummy — actuarial table
A30: 51 | B30: 1.84 | C30: Dummy — actuarial table
... A33: 54 | B33: 2.21 | C33: Dummy — actuarial table
A35: D. ANNUAL PROBABILITY OF LOCK-IN TERMINATION (claim or voluntary lapse)
A36: Lock-in ends on FIRST claim. Near-zero lapse assumed (Premium Promise anti-lapse effect).
A37: Age | B37: P(termination this year) | C37: Note
A38: 40 | B38: 0.12 | C38: ≈ claim freq + tiny lapse
A39: 41 | B39: 0.126 | C39: ≈ claim freq + tiny lapse
A40: 42 | B40: 0.132 | C40: ≈ claim freq + tiny lapse
A41: 43 | B41: 0.139 | C41: ≈ claim freq + tiny lapse
A42: 44 | B42: 0.146 | C42: ≈ claim freq + tiny lapse
A43: 45 | B43: 0.155 | C43: ≈ claim freq + tiny lapse
A44: 46 | B44: 0.164 | C44: ≈ claim freq + tiny lapse
...

Sheet Projection
A1: YEAR-BY-YEAR PROJECTION — EXPECTED CLAIMS DURING LOCK-IN PERIOD
A2: Col E = Base PP × Morbidity Factor × (1+Med Inflation)^t | Col F = survival probability (in lock-in) | Col G = expected claims weighted by survival | Col H = PV of Col G
A3: Year | B3: Age | C3: Morbidity Factor | D3: Medical Inflation Adj | E3: Age-Adj Pure Premium (₹) | F3: Prob Still in Lock-in | G3: Weighted Expected Claims (₹) | H3: Discount Factor | I3: PV of Exp. Claims (₹)
A4: 1 | B4: 40 | C4: =Assumptions!B19 -> 1 | D4: =POWER(1+Assumptions!$B$8,0) -> 1 | E4: =Assumptions!$B$14*C4*D4 -> 10200 | F4: =1-Assumptions!B38 -> 0.88 | G4: =E4*F4 -> 8976 | H4: =1/POWER(1+Assumptions!$B$7,1) -> 0.93457944 | I4: =G4*H4 -> 8388.785
A5: 2 | B5: 41 | C5: =Assumptions!B20 -> 1.05 | D5: =POWER(1+Assumptions!$B$8,1) -> 1.08 | E5: =Assumptions!$B$14*C5*D5 -> 11566.8 | F5: =F4*(1-Assumptions!B39) -> 0.76912 | G5: =E5*F5 -> 8896.2572 | H5: =1/POWER(1+Assumptions!$B$7,2) -> 0.87343873 | I5: =G5*H5 -> 7770.3356
A6: 3 | B6: 42 | C6: =Assumptions!B21 -> 1.1 | D6: =POWER(1+Assumptions!$B$8,2) -> 1.1664 | E6: =Assumptions!$B$14*C6*D6 -> 13087.008 | F6: =F5*(1-Assumptions!B40) -> 0.66759616 | G6: =E6*F6 -> 8736.8363 | H6: =1/POWER(1+Assumptions!$B$7,3) -> 0.81629788 | I6: =G6*H6 -> 7131.8609
A7: 4 | B7: 43 | C7: =Assumptions!B22 -> 1.16 | D7: =POWER(1+Assumptions!$B$8,3) -> 1.259712 | E7: =Assumptions!$B$14*C7*D7 -> 14904.912 | F7: =F6*(1-Assumptions!B41) -> 0.57480029 | G7: =E7*F7 -> 8567.348 | H7: =1/POWER(1+Assumptions!$B$7,4) -> 0.76289521 | I7: =G7*H7 -> 6535.9888
A8: 5 | B8: 44 | C8: =Assumptions!B23 -> 1.22 | D8: =POWER(1+Assumptions!$B$8,4) -> 1.360489 | E8: =Assumptions!$B$14*C8*D8 -> 16929.925 | F8: =F7*(1-Assumptions!B42) -> 0.49087945 | G8: =E8*F8 -> 8310.5521 | H8: =1/POWER(1+Assumptions!$B$7,5) -> 0.71298618 | I8: =G8*H8 -> 5925.3088
A9: 6 | B9: 45 | C9: =Assumptions!B24 -> 1.29 | D9: =POWER(1+Assumptions!$B$8,5) -> 1.4693281 | E9: =Assumptions!$B$14*C9*D9 -> 19333.419 | F9: =F8*(1-Assumptions!B43) -> 0.41479314 | G9: =E9*F9 -> 8019.3694 | H9: =1/POWER(1+Assumptions!$B$7,6) -> 0.66634222 | I9: =G9*H9 -> 5343.6445
A10: 7 | B10: 46 | C10: =Assumptions!B25 -> 1.37 | D10: =POWER(1+Assumptions!$B$8,6) -> 1.5868743 | E10: =Assumptions!$B$14*C10*D10 -> 22174.982 | F10: =F9*(1-Assumptions!B44) -> 0.34676706 | G10: =E10*F10 -> 7689.5533 | H10: =1/POWER(1+Assumptions!$B$7,7) -> 0.62274974 | I10: =G10*H10 -> 4788.6673
A11: 8 | B11: 47 | C11: =Assumptions!B26 -> 1.45 | D11: =POWER(1+Assumptions!$B$8,7) -> 1.7138243 | E11: =Assumptions!$B$14*C11*D11 -> 25347.461 | F11: =F10*(1-Assumptions!B45) -> 0.28642959 | G11: =E11*F11 -> 7260.2629 | H11: =1/POWER(1+Assumptions!$B$7,8) -> 0.5820091 | I11: =G11*H11 -> 4225.5391
A12: 9 | B12: 48 | C12: =Assumptions!B27 -> 1.54 | D12: =POWER(1+Assumptions!$B$8,8) -> 1.8509302 | E12: =Assumptions!$B$14*C12*D12 -> 29074.412 | F12: =F11*(1-Assumptions!B46) -> 0.23344012 | G12: =E12*F12 -> 6787.1341 | H12: =1/POWER(1+Assumptions!$B$7,9) -> 0.54393374 | I12: =G12*H12 -> 3691.7513
A13: 10 | B13: 49 | C13: =Assumptions!B28 -> 1.63 | D13: =POWER(1+Assumptions!$B$8,9) -> 1.9990046 | E13: =Assumptions!$B$14*C13*D13 -> 33235.451 | F13: =F12*(1-Assumptions!B47) -> 0.18768586 | G13: =E13*F13 -> 6237.824 | H13: =1/POWER(1+Assumptions!$B$7,10) -> 0.50834929 | I13: =G13*H13 -> 3170.9934
A14: 11 | B14: 50 | C14: =Assumptions!B29 -> 1.73 | D14: =POWER(1+Assumptions!$B$8,10) -> 2.158925 | E14: =Assumptions!$B$14*C14*D14 -> 38096.391 | F14: =F13*(1-Assumptions!B48) -> 0.1486472 | G14: =E14*F14 -> 5662.9217 | H14: =1/POWER(1+Assumptions!$B$7,11) -> 0.4750928 | I14: =G14*H14 -> 2690.4133
A15: 12 | B15: 51 | C15: =Assumptions!B30 -> 1.84 | D15: =POWER(1+Assumptions!$B$8,11) -> 2.331639 | E15: =Assumptions!$B$14*C15*D15 -> 43760.201 | F15: =F14*(1-Assumptions!B49) -> 0.11579617 | G15: =E15*F15 -> 5067.2635 | H15: =1/POWER(1+Assumptions!$B$7,12) -> 0.44401196 | I15: =G15*H15 -> 2249.9256
A16: 13 | B16: 52 | C16: =Assumptions!B31 -> 1.96 | D16: =POWER(1+Assumptions!$B$8,12) -> 2.5181701 | E16: =Assumptions!$B$14*C16*D16 -> 50343.257 | F16: =F15*(1-Assumptions!B50) -> 0.088584067 | G16: =E16*F16 -> 4459.6105 | H16: =1/POWER(1+Assumptions!$B$7,13) -> 0.41496445 | I16: =G16*H16 -> 1850.5798
A17: 14 | B17: 53 | C17: =Assumptions!B32 -> 2.08 | D17: =POWER(1+Assumptions!$B$8,13) -> 2.7196237 | E17: =Assumptions!$B$14*C17*D17 -> 57699.537 | F17: =F16*(1-Assumptions!B51) -> 0.066438051 | G17: =E17*F17 -> 3833.4448 | H17: =1/POWER(1+Assumptions!$B$7,14) -> 0.38781724 | I17: =G17*H17 -> 1486.676
A18: 15 | B18: 54 | C18: =Assumptions!B33 -> 2.21 | D18: =POWER(1+Assumptions!$B$8,14) -> 2.9371936 | E18: =Assumptions!$B$14*C18*D18 -> 66210.219 | F18: =F17*(1-Assumptions!B52) -> 0.048765529 | G18: =E18*F18 -> 3228.7763 | H18: =1/POWER(1+Assumptions!$B$7,15) -> 0.36244602 | I18: =G18*H18 -> 1170.2571
A19: TOTAL / SUM | E19: =SUM(E4:E18) -> 451963.97 | F19: — | G19: =SUM(G4:G18) -> 101733.15 | H19: — | I19: =SUM(I4:I18) -> 66420.726

Sheet Premium Calculation
A1: LEVEL PREMIUM DERIVATION — PREMIUM PROMISE PRICING
A2: Solve for P such that: P × Annuity Factor = PV(Expected Claims) + PV(Expenses)
A3: STEP 1 — Present Value of Expected Claims
A4: PV of Expected Claims (from Projection sheet, Col I sum) | B4: =Projection!I19 -> 66420.726 | C4: Sum of discounted weighted claims over lock-in
A6: STEP 2 — Level Premium Annuity Factor
A7: PV of ₹1 per year paid at start of each year, weighted by survival probability
A8: Year | B8: Survival-Weighted Discount Factor | C8: Note
A9: Year 1 (Age 40) | B9: =1*Projection!H4 -> 0.93457944 | C9: Surv(t-1) × DF(t)
A10: Year 2 (Age 41) | B10: =Projection!F4*Projection!H5 -> 0.76862608 | C10: Surv(t-1) × DF(t)
A11: Year 3 (Age 42) | B11: =Projection!F5*Projection!H6 -> 0.62783102 | C11: Surv(t-1) × DF(t)
A12: Year 4 (Age 43) | B12: =Projection!F6*Projection!H7 -> 0.50930591 | C12: Surv(t-1) × DF(t)
A13: Year 5 (Age 44) | B13: =Projection!F7*Projection!H8 -> 0.40982467 | C13: Surv(t-1) × DF(t)
A14: Year 6 (Age 45) | B14: =Projection!F8*Projection!H9 -> 0.3270937 | C14: Surv(t-1) × DF(t)
A15: Year 7 (Age 46) | B15: =Projection!F9*Projection!H10 -> 0.25831232 | C15: Surv(t-1) × DF(t)
A16: Year 8 (Age 47) | B16: =Projection!F10*Projection!H11 -> 0.20182159 | C16: Surv(t-1) × DF(t)
A17: Year 9 (Age 48) | B17: =Projection!F11*Projection!H12 -> 0.15579872 | C17: Surv(t-1) × DF(t)
A18: Year 10 (Age 49) | B18: =Projection!F12*Projection!H13 -> 0.11866912 | C18: Surv(t-1) × DF(t)
A19: Year 11 (Age 50) | B19: =Projection!F13*Projection!H14 -> 0.089168198 | C19: Surv(t-1) × DF(t)
A20: Year 12 (Age 51) | B20: =Projection!F14*Projection!H15 -> 0.066001133 | C20: Surv(t-1) × DF(t)
A21: Year 13 (Age 52) | B21: =Projection!F15*Projection!H16 -> 0.048051292 | C21: Surv(t-1) × DF(t)
... A23: Year 15 (Age 54) | B23: =Projection!F17*Projection!H18 -> 0.024080207 | C23: Surv(t-1) × DF(t)
A24: Sum of Annuity Factors (= PV of ₹1 annuity over lock-in) | B24: =SUM(B9:B23) -> 4.5735178
A26: STEP 3 — Level Pure Premium
A27: Level Pure Premium P = PV(Claims) ÷ Annuity Factor | B27: =B4/B24 -> 14522.897 | C27: Annual premium ignoring expenses & profit
A29: STEP 4 — Gross (Office) Premium
A30: Expense loading (% of pure premium) | B30: =Assumptions!B9 -> 0.2
A31: Profit margin (% of gross premium) | B31: =Assumptions!B10 -> 0.1
A32: Gross Premium = Pure Premium × (1 + Expense%) ÷ (1 − Profit%) | B32: =B27*(1+B30)/(1-B31) -> 19363.862 | C32: ← Final answer: annual locked premium
A34: STEP 5 — CROSS-CHECKS & SENSE CHECKS
A35: Annual renewal premium at age 40 (no lock-in) | B35: =Assumptions!B14*(1+Assumptions!B9)/(1-Assumptions!B10) -> 13600 | C35: Should be < Level Premium (level loads for future)
A36: Level premium loading vs annual renewal (₹) | B36: =B32-B35 -> 5763.8621 | C36: Front-load margin per year
A37: Lock-in period expected (years) | B37: =SUMPRODUCT(Projection!F4:F18)/1 -> 5.3197427 | C37: Sum of survival probs ≈ expected years in lock-in
A38: PV of gross premiums (at level P) | B38: =B32*B24 -> 88560.969 | C38: Should ≈ PV Claims + expenses + profit
A39: Loss ratio (PV Claims / PV Gross Premiums) | B39: =B4/(B32*B24) -> 0.75 | C39: Typical range 60%–75% for health

Sheet Model Notes
A1: MODEL NOTES & METHODOLOGY
A2: PURPOSE | B2: Illustrates level-premium pricing for a health policy with a premium lock-in (Premium Promise). All numerical inputs are dummy values for exam/educational use.
A3: STRUCTURE | B3: 1. Assumptions sheet — all inputs (blue cells) editable. 2. Projection sheet — year-by-year expected claims discounted to PV. 3. Premium Calculation sheet — annuity factor, pure premium, gross premium. 4. This Notes sheet.
A4: MORBIDITY | B4: Age-morbidity relativities scale the base pure premium (claim freq × severity at age 40) to reflect rising health costs as the insured ages. In practice, these come from a credible claims experience study or reinsurer tables.
A5: LOCK-IN DECREMENT | B5: The lock-in ends on FIRST CLAIM or age 55. The survival column (Col F, Projection) models the probability of still being within the lock-in at each year-end. Near-zero voluntary lapse is assumed due to the Premium Promise anti-lapse incentive.
A6: ANNUITY FACTOR | B6: Standard actuarial present-value annuity but with a survival decrement for lock-in exit. Analogous to a temporary life annuity in life insurance, where death is replaced by first-claim exit.
A7: MEDICAL INFLATION | B7: Applied as a compounding factor on the base pure premium each year, independently of the morbidity age loading. Both forces — aging and medical inflation — drive up the cost the level premium must prefund.
A8: GROSS PREMIUM FORMULA | B8: Gross P = Pure P × (1 + Expense%) / (1 − Profit%). This ensures expense loading is applied first, then profit is taken as a % of the final gross premium.
A9: EXAM ANGLE | B9: SA1 / SP2 candidates: note that this model mirrors a with-profits endowment or annuity pricing structure. The key insight is that the level premium must be set above the current annual renewal rate to prefund the higher costs in later lock-in years. Reserves must be held for the excess of future obligations over future premiums — a prospective reserve analogous to a life policy reserve.
