Workbook

Sheet 📋 Contents
B2: SP1 Healthcare Reserving Model | Chapter 21 Reference
B4: Sheet | C4: Tab Name | D4: Description | E4: Reserve Types Covered
B5: 📋 Contents | C5: This sheet | D5: Navigation and model guide | E5: –
B6: ⚙️ Assumptions | C6: Global Assumptions | D6: All input assumptions: discount rates, inflation, development factors | E6: All products
B7: 🏥 PMI | C7: Private Medical Insurance | D7: Short-term product: UPR, URR/AURR, IBNR (Chain Ladder), Claims in Transit, Outstanding Claims, IBNER, Reopened Claims | E7: UPR · URR · IBNR · IBNER · In-Transit · Reopened
B8: 🛡️ CI | C8: Critical Illness | D8: Long-term product: Policy reserve (EPV), IBNR (Chain Ladder), Outstanding Claims, IBNER, Reopened Claims | E8: Policy Res · IBNR · IBNER · Reopened
B9: 💼 IP | C9: Income Protection | D9: Long-term product: Policy reserve (continuance table), Active Claims Reserve, IBNR, IBNER, Reopened Claims | E9: Policy Res · Active Claims · IBNR · IBNER · Reopened
B10: 🏡 LTCI | C10: Long Term Care Insurance | D10: Long-term product: Policy reserve (continuance table), Active Claims Reserve, IBNR, IBNER, Reopened Claims | E10: Policy Res · Active Claims · IBNR · IBNER · Reopened
B11: 📊 Summary | C11: Reserve Summary | D11: Consolidated reserve summary across all four products with commentary | E11: All reserve types
B14: Colour Key
B15: ■ Sample | C15: Blue text on amber = Hardcoded INPUT (user changes these)
B16: ■ Sample | C16: Black text on white = FORMULA (auto-calculated)
B17: ■ Sample | C17: Green text = Cross-sheet LINK
B18: ■ Sample | C18: Blue shading = Section / sub-header
B19: ■ Sample | C19: Red shading = Watch / sensitivity cell
B22: SP1 Ch.21 Concept: Reserves may be calculated for: published accounts | solvency supervision | internal management | premium rating | M&A valuation | investment strategy | reinsurance assessment. The basis (best estimate vs prudent) differs by purpose.

Sheet ⚙️ Assumptions
B2: ⚙️ Global Assumptions — All inputs on this sheet drive the product tabs
B4: A. Valuation Date & General
B5: Parameter | C5: Value | D5: Units | E5: Notes
B6: Valuation Date | C6: 31/12/2024 | D6: Date | E6: Balance sheet date
B7: Discount Rate | C7: 0.04 | D7: % | E7: Risk-free rate for EPV calculations
B8: Expense Inflation | C8: 0.035 | D8: % | E8: Annual expense inflation assumption
B9: Medical Inflation (PMI) | C9: 0.06 | D9: % | E9: Medical cost trend – SP1 key assumption
B10: Earnings Inflation (IP) | C10: 0.04 | D10: % | E10: Linked to salary for IP benefits
B11: Reserving Purpose | C11: Published Accounts | D11: – | E11: Affects prudence margin – see Ch.21 S1
B12: Prudence Margin | C12: 0.05 | D12: % | E12: Added to best-estimate for solvency basis
B14: B. Chain Ladder Development Factors (used for IBNR on all products)
B15: Development Period | C15: PMI Factor | D15: CI Factor | E15: IP Factor | F15: LTCI Factor
B16: 0→1 | C16: 2.5 | D16: 3.2 | E16: 4.1 | F16: 5.5
B17: 1→2 | C17: 1.45 | D17: 1.8 | E17: 2.2 | F17: 3.1
B18: 2→3 | C18: 1.18 | D18: 1.35 | E18: 1.55 | F18: 2
B19: 3→4 | C19: 1.08 | D19: 1.15 | E19: 1.25 | F19: 1.45
B20: 4→5 | C20: 1.03 | D20: 1.06 | E20: 1.1 | F20: 1.2
B21: 5→Ult | C21: 1.01 | D21: 1.02 | E21: 1.04 | F21: 1.08
B23: C. IP / LTCI Continuance Table Assumptions
B24: Parameter | C24: IP | D24: LTCI | E24: Units | F24: Notes
B25: Initial Recovery Rate (pa) | C25: 0.25 | D25: 0.12 | E25: % | F25: Probability active claimant recovers in year
B26: Mortality Rate on Claim (pa) | C26: 0.03 | D26: 0.08 | E26: % | F26: Probability claimant dies while claiming
B27: Policy Termination Date (yrs) | C27: 10 | D27: 25 | E27: Years | F27: Max remaining term used for EPV
B28: Average Age on Claim | C28: 45 | D28: 72 | E28: Years | F28: Used to select mortality/recovery rates
B29: Deferred Period (weeks) | C29: 26 | D29: 0 | E29: Weeks | F29: IP only – weeks before benefit starts
B31: D. IBNER & Reopened Claims Factors
B32: Parameter | C32: PMI | D32: CI | E32: IP | F32: LTCI
B33: IBNER Factor (% of O/S Claims Reserve) | C33: 0.05 | D33: 0.08 | E33: 0.1 | F33: 0.12
B34: Reopened Claims Rate (% of paid claims) | C34: 0.02 | D34: 0.015 | E34: 0.025 | F34: 0.01
B35: Average Reopened Claim Cost (£) | C35: 1500 | D35: 25000 | E35: 8000 | F35: 12000
B37: SP1 Ch.21 S3: Development factors are derived from run-off triangles (chain ladder). IBNER (incurred but not enough reported) = adjustment to outstanding reported claims reserve where the actuary believes case estimates are systematically under/over-stated.

Sheet 🏥 PMI
B2: 🏥 Private Medical Insurance (PMI) — Reserving Model
B4: SP1 Ch.21 S2.2: PMI is SHORT-TERM insurance. Reserves required: UPR (retrospective – proportion of premium unearned) | URR/AURR (prospective – cost of unexpired risk) | IBNR (chain ladder) | Claims in Transit | Outstanding Claims | IBNER | Reopened Claims.
B6: A. Unearned Premium Reserve (UPR) — Retrospective Approach
B7: SP1: UPR = proportion of risk-related premium relating to unexpired period. Initial expenses (commission) are excluded as already earned. Assuming uniform risk over the year: UPR = (days unexpired / 365) × risk-related premium.
B8: Policy | C8: Annual Premium (£) | D8: Initial Exp % (commission) | E8: Risk-Related Premium (£) | F8: Days Expired | G8: Days Unexpired | H8: UPR (£)
B9: Policy A | C9: 1200 | D9: 0.15 | E9: =C9*(1-D9) -> 1020 | F9: 180 | G9: =365-F9 -> 185 | H9: =E9*(G9/365) -> 516.9863
B10: Policy B | C10: 2400 | D10: 0.1 | E10: =C10*(1-D10) -> 2160 | F10: 90 | G10: =365-F10 -> 275 | H10: =E10*(G10/365) -> 1627.3973
B11: Policy C | C11: 600 | D11: 0.12 | E11: =C11*(1-D11) -> 528 | F11: 270 | G11: =365-F11 -> 95 | H11: =E11*(G11/365) -> 137.42466
B12: Policy D | C12: 3600 | D12: 0.08 | E12: =C12*(1-D12) -> 3312 | F12: 45 | G12: =365-F12 -> 320 | H12: =E12*(G12/365) -> 2903.6712
B13: Policy E | C13: 800 | D13: 0.15 | E13: =C13*(1-D13) -> 680 | F13: 200 | G13: =365-F13 -> 165 | H13: =E13*(G13/365) -> 307.39726
B14: TOTAL UPR | H14: =SUM(H9:H13) -> 5492.8767
B16: B. Unexpired Risk Reserve (URR) & Additional Unexpired Risk Reserve (AURR) — Prospective Approach
B17: SP1: URR = estimate of what is actually needed to cover unexpired risk (prospective). AURR = MAX(0, URR – UPR). If AURR > 0, premiums are insufficient. URR = Expected future loss ratio × risk-related premium unexpired.
B18: Parameter | C18: Value | D18: Source
B19: Total UPR (from Section A) | C19: =H14 -> 5492.8767 | D19: Linked from Section A
B20: Expected Future Loss Ratio | C20: 0.72 | D20: From experience analysis
B21: URR = ELR × UPR | C21: =C20*C19 -> 3954.8712
B22: AURR = MAX(0, URR – UPR) | C22: =MAX(0,C21-C19) -> 0
B24: C. IBNR Reserve — Chain Ladder (Statistical Method)
B25: Cumulative paid claims (£000s). Blue cells = actual data. Green cells = projected using development factors from ⚙️ Assumptions tab. Factor col: PMI = column C of section B in Assumptions.
B26: Chain Ladder — PMI | IBNR Reserve
B27: SP1 Ch.21 S3.2: Statistical method – past claims development patterns are used to project incomplete diagonals to ultimate. IBNR = Ultimate – Latest Paid.
B28: Accident Year | C28: Dev 0 | D28: Dev 1 | E28: Dev 2 | F28: Dev 3 | G28: Dev 4 | H28: Dev 5 | I28: Latest Paid | J28: Ultimate | K28: IBNR
B29: 2019 | C29: 820 | D29: 1190 | E29: 1370 | F29: 1450 | G29: 1480 | H29: 1495 | I29: =H29 -> 1495 | J29: =H29 -> 1495 | K29: =J29-I29 -> 0
B30: 2020 | C30: 750 | D30: 1090 | E30: 1255 | F30: 1330 | G30: 1360 | H30: =G30*H35 -> 1373.6 | I30: =G30 -> 1360 | J30: =H30 -> 1373.6 | K30: =J30-I30 -> 13.6
B31: 2021 | C31: 880 | D31: 1276 | E31: 1468 | F31: 1556 | G31: =F31*G35 -> 1602.68 | H31: =G31*H35 -> 1618.7068 | I31: =F31 -> 1556 | J31: =H31 -> 1618.7068 | K31: =J31-I31 -> 62.7068
B32: 2022 | C32: 960 | D32: 1392 | E32: 1602 | F32: =E32*F35 -> 1730.16 | G32: =F32*G35 -> 1782.0648 | H32: =G32*H35 -> 1799.8854 | I32: =E32 -> 1602 | J32: =H32 -> 1799.8854 | K32: =J32-I32 -> 197.88545
B33: 2023 | C33: 1050 | D33: 1523 | E33: =D33*E35 -> 1797.14 | F33: =E33*F35 -> 1940.9112 | G33: =F33*G35 -> 1999.1385 | H33: =G33*H35 -> 2019.1299 | I33: =D33 -> 1523 | J33: =H33 -> 2019.1299 | K33: =J33-I33 -> 496.12992
B34: 2024 | C34: 1180 | D34: =C34*D35 -> 1711 | E34: =D34*E35 -> 2018.98 | F34: =E34*F35 -> 2180.4984 | G34: =F34*G35 -> 2245.9134 | H34: =G34*H35 -> 2268.3725 | I34: =C34 -> 1180 | J34: =H34 -> 2268.3725 | K34: =J34-I34 -> 1088.3725
B35: Development Factor | C35: ='⚙️ Assumptions'!C16 -> 2.5 | D35: ='⚙️ Assumptions'!C17 -> 1.45 | E35: ='⚙️ Assumptions'!C18 -> 1.18 | F35: ='⚙️ Assumptions'!C19 -> 1.08 | G35: ='⚙️ Assumptions'!C20 -> 1.03 | H35: ='⚙️ Assumptions'!C21 -> 1.01
B36: TOTAL IBNR | K36: =SUM(K29:K34) -> 1858.6947
B38: D. Claims in Transit Reserve (Pipeline Claims)
B39: SP1 Ch.21: Claims reported but not yet assessed or recorded. Estimated as: average number of pipeline claims × average cost per claim. Can be significant for emergency PMI claims.
B40: Parameter | C40: Value | D40: Notes
B41: Average pipeline claims per week | C41: 12 | D41: Admin lag estimate
B42: Average weeks in pipeline | C42: 2 | D42: Processing time
B43: Average cost per pipeline claim (£) | C43: 1800 | D43: Based on experience
B44: Claims in Transit Reserve (£) | C44: =C41*C42*C43 -> 43200
B46: E. Outstanding Reported Claims Reserve
B47: SP1 Ch.21: Reserve for claims notified but not yet fully settled. Case estimate or statistical method. PMI: few long-tail claims (chronic conditions excluded); reserve typically small.
...

Sheet 🛡️ CI
B2: 🛡️ Critical Illness (CI) — Reserving Model
B4: SP1 Ch.21 S2.1: CI is LONG-TERM insurance. Key reserve: prospective policy reserve = EPV(future claims + expenses) – EPV(future premiums). Also: IBNR (late notification increasingly common in CI – policyholders discover cover for conditions years after diagnosis), Outstanding Claims, IBNER, Reopened.
B6: A. Policy Reserve — Prospective Method (EPV of Future Cashflows)
B7: Reserve = EPV(future claims) + EPV(future expenses) – EPV(future premiums). CI is a lump sum benefit on diagnosis of a specified condition. Probability of claim increases with age. Discount at rate from Assumptions.
B8: Cohort | C8: Policies In-Force | D8: Sum Insured (£) | E8: Annual Premium (£) | F8: Annual Expense (£) | G8: Claim Prob (pa) | H8: Remaining Term (yrs) | I8: EPV Claims (£) | J8: EPV Expenses (£) | K8: EPV Premiums (£)
B9: Age 35-44 | C9: 500 | D9: 50000 | E9: 900 | F9: 80 | G9: 0.003 | H9: 20 | I9: =C9*D9*G9*((1-(1+0.04)^(-H9))/0.04) -> 1019274.5 | J9: =C9*F9*((1-(1+0.04)^(-H9))/0.04) -> 543613.05 | K9: =C9*E9*((1-(1+0.04)^(-H9))/0.04) -> 6115646.9
B10: Age 45-54 | C10: 380 | D10: 75000 | E10: 1400 | F10: 95 | G10: 0.008 | H10: 15 | I10: =C10*D10*G10*((1-(1+0.04)^(-H10))/0.04) -> 2534992.3 | J10: =C10*F10*((1-(1+0.04)^(-H10))/0.04) -> 401373.79 | K10: =C10*E10*((1-(1+0.04)^(-H10))/0.04) -> 5914982.1
B11: Age 55-64 | C11: 210 | D11: 100000 | E11: 2200 | F11: 110 | G11: 0.018 | H11: 10 | I11: =C11*D11*G11*((1-(1+0.04)^(-H11))/0.04) -> 3065918.6 | J11: =C11*F11*((1-(1+0.04)^(-H11))/0.04) -> 187361.69 | K11: =C11*E11*((1-(1+0.04)^(-H11))/0.04) -> 3747233.9
B12: Age 65-74 | C12: 90 | D12: 60000 | E12: 3100 | F12: 130 | G12: 0.035 | H12: 5 | I12: =C12*D12*G12*((1-(1+0.04)^(-H12))/0.04) -> 841394.42 | J12: =C12*F12*((1-(1+0.04)^(-H12))/0.04) -> 52086.321 | K12: =C12*E12*((1-(1+0.04)^(-H12))/0.04) -> 1242058.4
B13: TOTAL Policy Reserve = EPV Claims + EPV Exp – EPV Prem | I13: =SUM(I9:I12) -> 7461579.8 | J13: =SUM(J9:J12) -> 1184434.9 | K13: =SUM(K9:K12) -> 17019921
B14: NET POLICY RESERVE (EPV Claims + EPV Exp – EPV Prem) | I14: =I13+J13-K13 -> -8373906.6
B16: B. IBNR Reserve — Chain Ladder (Statistical Method)
B17: SP1 KEY POINT: CI IBNR can be SUBSTANTIAL. Policyholders may not realise they were covered for a condition until years after diagnosis (e.g., broker discovers entitlement). Late notification is increasingly common.
B18: Chain Ladder — CI | IBNR Reserve
B19: SP1 Ch.21 S3.2: Statistical method – past claims development patterns are used to project incomplete diagonals to ultimate. IBNR = Ultimate – Latest Paid.
B20: Accident Year | C20: Dev 0 | D20: Dev 1 | E20: Dev 2 | F20: Dev 3 | G20: Dev 4 | H20: Dev 5 | I20: Latest Paid | J20: Ultimate | K20: IBNR
B21: 2019 | C21: 620 | D21: 1984 | E21: 3573 | F21: 4644 | G21: 5108 | H21: 5210 | I21: =H21 -> 5210 | J21: =H21 -> 5210 | K21: =J21-I21 -> 0
B22: 2020 | C22: 580 | D22: 1856 | E22: 3341 | F22: 4343 | G22: 4778 | H22: =G22*H27 -> 4873.56 | I22: =G22 -> 4778 | J22: =H22 -> 4873.56 | K22: =J22-I22 -> 95.56
B23: 2021 | C23: 710 | D23: 2272 | E23: 4090 | F23: 5317 | G23: =F23*G27 -> 5636.02 | H23: =G23*H27 -> 5748.7404 | I23: =F23 -> 5317 | J23: =H23 -> 5748.7404 | K23: =J23-I23 -> 431.7404
B24: 2022 | C24: 760 | D24: 2432 | E24: 4378 | F24: =E24*F27 -> 5034.7 | G24: =F24*G27 -> 5336.782 | H24: =G24*H27 -> 5443.5176 | I24: =E24 -> 4378 | J24: =H24 -> 5443.5176 | K24: =J24-I24 -> 1065.5176
B25: 2023 | C25: 840 | D25: 2688 | E25: =D25*E27 -> 3628.8 | F25: =E25*F27 -> 4173.12 | G25: =F25*G27 -> 4423.5072 | H25: =G25*H27 -> 4511.9773 | I25: =D25 -> 2688 | J25: =H25 -> 4511.9773 | K25: =J25-I25 -> 1823.9773
B26: 2024 | C26: 920 | D26: =C26*D27 -> 1656 | E26: =D26*E27 -> 2235.6 | F26: =E26*F27 -> 2570.94 | G26: =F26*G27 -> 2725.1964 | H26: =G26*H27 -> 2779.7003 | I26: =C26 -> 920 | J26: =H26 -> 2779.7003 | K26: =J26-I26 -> 1859.7003
B27: Development Factor | C27: ='⚙️ Assumptions'!D16 -> 3.2 | D27: ='⚙️ Assumptions'!D17 -> 1.8 | E27: ='⚙️ Assumptions'!D18 -> 1.35 | F27: ='⚙️ Assumptions'!D19 -> 1.15 | G27: ='⚙️ Assumptions'!D20 -> 1.06 | H27: ='⚙️ Assumptions'!D21 -> 1.02
B28: TOTAL IBNR | K28: =SUM(K21:K26) -> 5276.4957
B30: C. Outstanding Claims Reserve (Claims in Assessment Period)
B31: SP1: CI claims in assessment period = reported but not yet fully verified. CI has a claims verification/assessment process; claims may remain outstanding for months while medical evidence is gathered.
B32: Claim Ref | C32: Sum Insured (£) | D32: Prob of Valid Claim | E32: Expected Payout (£)
B33: CI-001 | C33: 100000 | D33: 0.9 | E33: =C33*D33 -> 90000
B34: CI-002 | C34: 75000 | D34: 0.7 | E34: =C34*D34 -> 52500
B35: CI-003 | C35: 50000 | D35: 0.95 | E35: =C35*D35 -> 47500
B36: CI-004 | C36: 200000 | D36: 0.4 | E36: =C36*D36 -> 80000
B37: CI-005 | C37: 60000 | D37: 0.85 | E37: =C37*D37 -> 51000
B38: TOTAL Outstanding Claims | E38: =SUM(E33:E37) -> 321000
B40: D. IBNER Reserve | C40: =E38 -> 321000 | D40: 0.08
B41: Outstanding Claims Reserve | C41: =C40*D40 -> 25680
B42: IBNER Factor (from Assumptions) | C42: ='⚙️ Assumptions'!D35 -> 25000
B43: IBNER Reserve (£) | C43: =C41*C42 -> 642000000
B45: E. Reopened Claims Reserve | C45: =C46*C47 -> 0
B46: Total Claims Paid in Year (£) | C46: 8500000
B47: Reopened Claims Rate | C47: ='⚙️ Assumptions'!D36 -> 0
...

Sheet 💼 IP
B2: 💼 Income Protection (IP) — Reserving Model
B4: SP1 Ch.21 S2.1: IP is LONG-TERM insurance. Policy reserve = EPV(future claims) + EPV(expenses) – EPV(premiums). Active claims reserve uses CONTINUANCE TABLE (probability of remaining on claim) to value benefit annuity. Deferred period is key: IBNR arises when claimant is in deferred period and hasn't notified insurer.
B6: A. Active Claims Reserve — Continuance Table Method
B7: SP1 Ch.21: For IP claimants currently in payment, reserve = EPV of future benefit payments = benefit × continuance annuity. Continuance probability p(t) = prob still claiming at duration t. Reserve shown per claimant cohort; annuity discounted at assumptions rate.
B8: Claimant Cohort | C8: # Claimants | D8: Weekly Benefit (£) | E8: Avg Duration on Claim (wks) | F8: Recovery Rate (pa) | G8: Mortality Rate (pa) | H8: Remaining Term (yrs) | I8: Continuance Factor | J8: Active Claims Reserve (£)
B9: < 1 yr on claim | C9: 45 | D9: 350 | E9: 12 | F9: 0.3 | G9: 0.02 | H9: 8 | I9: =IF((F9+G9)=0,H9,(1-(1-F9-G9)^H9*(1+0.04)^(-H9))/(F9+G9+0.04)) -> 2.6849876 | J9: =C9*D9*52*I9 -> 2199004.8
B10: 1–2 yrs on claim | C10: 28 | D10: 420 | E10: 60 | F10: 0.18 | G10: 0.03 | H10: 7 | I10: =IF((F10+G10)=0,H10,(1-(1-F10-G10)^H10*(1+0.04)^(-H10))/(F10+G10+0.04)) -> 3.4162643 | J10: =C10*D10*52*I10 -> 2089113.9
B11: 2–5 yrs on claim | C11: 18 | D11: 380 | E11: 130 | F11: 0.1 | G11: 0.04 | H11: 5 | I11: =IF((F11+G11)=0,H11,(1-(1-F11-G11)^H11*(1+0.04)^(-H11))/(F11+G11+0.04)) -> 3.4074627 | J11: =C11*D11*52*I11 -> 1211966.3
B12: > 5 yrs on claim | C12: 9 | D12: 500 | E12: 280 | F12: 0.05 | G12: 0.06 | H12: 3 | I12: =IF((F12+G12)=0,H12,(1-(1-F12-G12)^H12*(1+0.04)^(-H12))/(F12+G12+0.04)) -> 2.4885675 | J12: =C12*D12*52*I12 -> 582324.8
B13: TOTAL Active Claims Reserve | J13: =SUM(J9:J12) -> 6082409.9
C14: =J13 -> 6082409.9
B15: B. Policy Reserve (Healthy Policyholders) — Prospective Method | C15: 0.10
B16: SP1 Ch.21 Q&A: Healthy policyholder reserve = EPV(future claim inceptions × benefit duration) + EPV(expenses) – EPV(premiums). Claim inception rate increases with age. Shown by age band. | C16: =C14*C15 -> 608240.99
B17: Age Band | C17: Policies | D17: Annual Premium (£) | E17: Annual Expense (£) | F17: Claim Inception Rate (pa) | G17: Avg Benefit Duration (yrs) | H17: Weekly Benefit (£) | I17: Remaining Term (yrs) | J17: Policy Reserve (£)
B18: 25–34 | C18: 320 | D18: 600 | E18: 50 | F18: 0.004 | G18: 1.5 | H18: 250 | I18: 30 | J18: =C18*(F18*H18*52*((1-(1+0.04)^(-G18))/0.04)+(E18)*((1-(1+0.04)^(-I18))/0.04)-D18*((1-(1+0.04)^(-I18))/0.04)) -> -3019630.1
B19: 35–44 | C19: 480 | D19: 850 | E19: 65 | F19: 0.008 | G19: 2 | H19: 350 | I19: 22 | J19: =C19*(F19*H19*52*((1-(1+0.04)^(-G19))/0.04)+(E19)*((1-(1+0.04)^(-I19))/0.04)-D19*((1-(1+0.04)^(-I19))/0.04)) -> -5313364.9
B20: 45–54 | C20: 380 | D20: 1200 | E20: 80 | F20: 0.018 | G20: 3 | H20: 420 | I20: 14 | J20: =C20*(F20*H20*52*((1-(1+0.04)^(-G20))/0.04)+(E20)*((1-(1+0.04)^(-I20))/0.04)-D20*((1-(1+0.04)^(-I20))/0.04)) -> -4081106.5
B21: 55–64 | C21: 160 | D21: 1800 | E21: 95 | F21: 0.035 | G21: 4.5 | H21: 500 | I21: 7 | J21: =C21*(F21*H21*52*((1-(1+0.04)^(-G21))/0.04)+(E21)*((1-(1+0.04)^(-I21))/0.04)-D21*((1-(1+0.04)^(-I21))/0.04)) -> -1048424.8
B22: TOTAL Policy Reserve (Healthy Lives) | J22: =SUM(J18:J21) -> -13462526
B24: C. IBNR Reserve — Chain Ladder (Statistical Method)
B25: SP1: IP IBNR arises from claimants in the DEFERRED PERIOD who have not yet notified the insurer. Can be substantial given long deferred periods (e.g., 26 weeks). Development pattern is longer-tailed than PMI. | J25: =C25*(F25*H25*52*((1-(1+0.04)^(-G25))/0.04)+(E25)*((1-(1+0.04)^(-I25))/0.04)-D25*((1-(1+0.04)^(-I25))/0.04)) -> 0
B26: Chain Ladder — IP | IBNR Reserve
B27: SP1 Ch.21 S3.2: Statistical method – past claims development patterns are used to project incomplete diagonals to ultimate. IBNR = Ultimate – Latest Paid.
B28: Accident Year | C28: Dev 0 | D28: Dev 1 | E28: Dev 2 | F28: Dev 3 | G28: Dev 4 | H28: Dev 5 | I28: Latest Paid | J28: Ultimate | K28: IBNR
B29: 2019 | C29: 480 | D29: 1968 | E29: 4330 | F29: 6495 | G29: 7144 | H29: 7430 | I29: =H29 -> 7430 | J29: =H29 -> 7430 | K29: =J29-I29 -> 0
B30: 2020 | C30: 510 | D30: 2091 | E30: 4600 | F30: 6900 | G30: 7590 | H30: =G30*H35 -> 7893.6 | I30: =G30 -> 7590 | J30: =H30 -> 7893.6 | K30: =J30-I30 -> 303.6
B31: 2021 | C31: 550 | D31: 2255 | E31: 4961 | F31: 7442 | G31: =F31*G35 -> 8186.2 | H31: =G31*H35 -> 8513.648 | I31: =F31 -> 7442 | J31: =H31 -> 8513.648 | K31: =J31-I31 -> 1071.648
B32: 2022 | C32: 590 | D32: 2419 | E32: 5322 | F32: =E32*F35 -> 6652.5 | G32: =F32*G35 -> 7317.75 | H32: =G32*H35 -> 7610.46 | I32: =E32 -> 5322 | J32: =H32 -> 7610.46 | K32: =J32-I32 -> 2288.46
B33: 2023 | C33: 630 | D33: 2583 | E33: =D33*E35 -> 4003.65 | F33: =E33*F35 -> 5004.5625 | G33: =F33*G35 -> 5505.0188 | H33: =G33*H35 -> 5725.2195 | I33: =D33 -> 2583 | J33: =H33 -> 5725.2195 | K33: =J33-I33 -> 3142.2195
B34: 2024 | C34: 680 | D34: =C34*D35 -> 1496 | E34: =D34*E35 -> 2318.8 | F34: =E34*F35 -> 2898.5 | G34: =F34*G35 -> 3188.35 | H34: =G34*H35 -> 3315.884 | I34: =C34 -> 680 | J34: =H34 -> 3315.884 | K34: =J34-I34 -> 2635.884
B35: Development Factor | C35: ='⚙️ Assumptions'!E16 -> 4.1 | D35: ='⚙️ Assumptions'!E17 -> 2.2 | E35: ='⚙️ Assumptions'!E18 -> 1.55 | F35: ='⚙️ Assumptions'!E19 -> 1.25 | G35: ='⚙️ Assumptions'!E20 -> 1.1 | H35: ='⚙️ Assumptions'!E21 -> 1.04
B36: TOTAL IBNR | K36: =SUM(K29:K34) -> 9441.8115
B38: D. IBNER Reserve
B39: Active Claims Reserve | C39: =J13 -> 6082409.9
B40: IBNER Factor (from Assumptions) | C40: 0.10
B41: IBNER Reserve (£) | C41: =C39*C40 -> 608240.99
B43: E. Reopened Claims Reserve | C43: =C44*C45 -> 0
B44: Total Claims Paid in Year (£) | C44: 6200000
B45: Reopened Claims Rate | C45: ='⚙️ Assumptions'!E36 -> 0
B46: Avg Reopened Claim Cost (£) | C46: =C44*C45 -> 0
...

Sheet 🏡 LTCI
B2: 🏡 Long Term Care Insurance (LTCI) — Reserving Model
B4: SP1: LTCI is LONG-TERM insurance. Pays benefit when policyholder cannot perform activities of daily living. Claims are very long-tailed. Continuance table critical: recovery rates low, mortality on claim significant. Development factors longest of all four products.
B6: A. Active Claims Reserve — Continuance Table Method
B7: SP1: LTCI active claims annuity uses low recovery rates and significant mortality. Benefits may be weekly/monthly care costs. Long durations make reserve very sensitive to assumptions (discount rate, recovery, mortality).
B8: Claimant Cohort | C8: # Claimants | D8: Weekly Benefit (£) | E8: Recovery Rate (pa) | F8: Mortality Rate (pa) | G8: Remaining Term (yrs) | H8: Continuance Factor | I8: Active Claims Reserve (£)
B9: Age < 75 | C9: 28 | D9: 600 | E9: 0.1 | F9: 0.06 | G9: 12 | H9: =IF((E9+F9)=0,G9,(1-(1-E9-F9)^G9*(1+0.04)^(-G9))/(E9+F9+0.04)) -> 4.6145914 | I9: =C9*D9*52*H9 -> 4031307.1
B10: Age 75–79 | C10: 35 | D10: 650 | E10: 0.06 | F10: 0.1 | G10: 8 | H10: =IF((E10+F10)=0,G10,(1-(1-E10-F10)^G10*(1+0.04)^(-G10))/(E10+F10+0.04)) -> 4.0943976 | I10: =C10*D10*52*H10 -> 4843672.3
B11: Age 80–84 | C11: 42 | D11: 700 | E11: 0.03 | F11: 0.15 | G11: 5 | H11: =IF((E11+F11)=0,G11,(1-(1-E11-F11)^G11*(1+0.04)^(-G11))/(E11+F11+0.04)) -> 3.1603585 | I11: =C11*D11*52*H11 -> 4831556.1
B12: Age 85+ | C12: 30 | D12: 750 | E12: 0.01 | F12: 0.25 | G12: 3 | H12: =IF((E12+F12)=0,G12,(1-(1-E12-F12)^G12*(1+0.04)^(-G12))/(E12+F12+0.04)) -> 2.1325245 | I12: =C12*D12*52*H12 -> 2495053.6
B13: TOTAL Active Claims Reserve | I13: =SUM(I9:I12) -> 16201589
B15: B. Policy Reserve (Healthy Policyholders) | C15: =I13 -> 16201589 | D15: 0.12
B16: EPV approach. LTCI claim inception rates increase sharply at older ages. Benefit is care costs per week; escalation clauses may apply. | C16: =C15*D15 -> 1944190.7
B17: Age Band | C17: Policies | D17: Annual Premium (£) | E17: Annual Expense (£) | F17: Inception Rate (pa) | G17: Avg Benefit Duration (yrs) | H17: Weekly Benefit (£) | I17: Remaining Term (yrs) | J17: Policy Reserve (£)
B18: 50–59 | C18: 250 | D18: 1800 | E18: 120 | F18: 0.003 | G18: 5 | H18: 500 | I18: 25 | J18: =C18*(F18*H18*52*((1-(1+0.04)^(-G18))/0.04)+E18*((1-(1+0.04)^(-I18))/0.04)-D18*((1-(1+0.04)^(-I18))/0.04)) -> -6474463
B19: 60–69 | C19: 310 | D19: 2400 | E19: 140 | F19: 0.012 | G19: 6 | H19: 600 | I19: 16 | J19: =C19*(F19*H19*52*((1-(1+0.04)^(-G19))/0.04)+E19*((1-(1+0.04)^(-I19))/0.04)-D19*((1-(1+0.04)^(-I19))/0.04)) -> -7555174.9
B20: 70–74 | C20: 180 | D20: 3200 | E20: 160 | F20: 0.04 | G20: 7 | H20: 700 | I20: 8 | J20: =C20*(F20*H20*52*((1-(1+0.04)^(-G20))/0.04)+E20*((1-(1+0.04)^(-I20))/0.04)-D20*((1-(1+0.04)^(-I20))/0.04)) -> -2111139.5
B21: 75–79 | C21: 90 | D21: 4000 | E21: 180 | F21: 0.09 | G21: 8 | H21: 750 | I21: 4 | J21: =C21*(F21*H21*52*((1-(1+0.04)^(-G21))/0.04)+E21*((1-(1+0.04)^(-I21))/0.04)-D21*((1-(1+0.04)^(-I21))/0.04)) -> 878916.13
B22: TOTAL Policy Reserve (Healthy Lives) | J22: =SUM(J18:J21) -> -15261861
B24: C. IBNR Reserve — Chain Ladder (Statistical Method)
B25: SP1: LTCI has the LONGEST development tail of all products. Claims can be notified years after care needs begin. Development factors much higher than PMI. Large IBNR expected.
B26: Chain Ladder — LTCI | IBNR Reserve
B27: SP1 Ch.21 S3.2: Statistical method – past claims development patterns are used to project incomplete diagonals to ultimate. IBNR = Ultimate – Latest Paid.
B28: Accident Year | C28: Dev 0 | D28: Dev 1 | E28: Dev 2 | F28: Dev 3 | G28: Dev 4 | H28: Dev 5 | I28: Latest Paid | J28: Ultimate | K28: IBNR
B29: 2019 | C29: 310 | D29: 1705 | E29: 5425 | F29: 10850 | G29: 15748 | H29: 17005 | I29: =H29 -> 17005 | J29: =H29 -> 17005 | K29: =J29-I29 -> 0
B30: 2020 | C30: 340 | D30: 1870 | E30: 5952 | F30: 11904 | G30: 17260 | H30: =G30*H35 -> 18640.8 | I30: =G30 -> 17260 | J30: =H30 -> 18640.8 | K30: =J30-I30 -> 1380.8
B31: 2021 | C31: 370 | D31: 2035 | E31: 6479 | F31: 12958 | G31: =F31*G35 -> 15549.6 | H31: =G31*H35 -> 16793.568 | I31: =F31 -> 12958 | J31: =H31 -> 16793.568 | K31: =J31-I31 -> 3835.568
B32: 2022 | C32: 400 | D32: 2200 | E32: 7007 | F32: =E32*F35 -> 10160.15 | G32: =F32*G35 -> 12192.18 | H32: =G32*H35 -> 13167.554 | I32: =E32 -> 7007 | J32: =H32 -> 13167.554 | K32: =J32-I32 -> 6160.5544
B33: 2023 | C33: 430 | D33: 2365 | E33: =D33*E35 -> 4730 | F33: =E33*F35 -> 6858.5 | G33: =F33*G35 -> 8230.2 | H33: =G33*H35 -> 8888.616 | I33: =D33 -> 2365 | J33: =H33 -> 8888.616 | K33: =J33-I33 -> 6523.616
B34: 2024 | C34: 460 | D34: =C34*D35 -> 1426 | E34: =D34*E35 -> 2852 | F34: =E34*F35 -> 4135.4 | G34: =F34*G35 -> 4962.48 | H34: =G34*H35 -> 5359.4784 | I34: =C34 -> 460 | J34: =H34 -> 5359.4784 | K34: =J34-I34 -> 4899.4784
B35: Development Factor | C35: ='⚙️ Assumptions'!F16 -> 5.5 | D35: ='⚙️ Assumptions'!F17 -> 3.1 | E35: ='⚙️ Assumptions'!F18 -> 2 | F35: ='⚙️ Assumptions'!F19 -> 1.45 | G35: ='⚙️ Assumptions'!F20 -> 1.2 | H35: ='⚙️ Assumptions'!F21 -> 1.08
B36: TOTAL IBNR | K36: =SUM(K29:K34) -> 22800.017
B38: D. IBNER Reserve
B39: Active Claims Reserve | C39: =I13 -> 16201589
B40: IBNER Factor (from Assumptions) | C40: 0.12
B41: IBNER Reserve (£) | C41: =C39*C40 -> 1944190.7
B43: E. Reopened Claims Reserve | C43: =C44*C45 -> 0
B44: Total Claims Paid in Year (£) | C44: 3800000
B45: Reopened Claims Rate | C45: ='⚙️ Assumptions'!F36 -> 0
B46: Avg Reopened Claim Cost (£) | C46: =C44*C45 -> 0
B47: Reopened Claims Reserve (£) | C47: =C44*C45 -> 0
...

Sheet 📊 Summary
B2: 📊 Reserve Summary | All Products | SP1 Chapter 21
B4: SP1 Ch.21 S1: Reserve basis depends on purpose. Published accounts → best estimate / slightly prudent. Solvency supervision → most prudent. Internal → best estimate. M&A → near best estimate.
B6: Consolidated Reserve Summary by Product and Reserve Type
B7: Reserve Type | C7: PMI (£) | D7: CI (£) | E7: IP (£) | F7: LTCI (£) | G7: Total (£) | H7: SP1 Ch.21 Reference
B8: Policy Reserve / UPR+AURR | C8: → see tab | D8: → see tab | E8: → see tab | F8: → see tab | H8: Long-term: EPV of future cashflows. Short-term: UPR (retrospective) + AURR (prospective top-up)
B9: Active Claims Reserve | C9: N/A | D9: N/A | E9: → see tab | F9: → see tab | H9: Continuance table annuity for claims in payment. IP: recovery/mortality. LTCI: very low recovery
B10: IBNR (Chain Ladder) | C10: → see tab | D10: → see tab | E10: → see tab | F10: → see tab | H10: Statistical. LTCI > IP > CI > PMI in tail length. CI: late notification increasingly common
B11: Outstanding / Transit Claims | C11: → see tab | D11: → see tab | E11: → see tab | F11: → see tab | H11: PMI: case estimates + in-transit pipeline. CI: assessment period claims. IP/LTCI: disability verification
B12: IBNER | C12: → see tab | D12: → see tab | E12: → see tab | F12: → see tab | H12: Adjustment to O/S reserve where case estimates systematically wrong. Separate for management info
B13: Reopened Claims | C13: → see tab | D13: → see tab | E13: → see tab | F13: → see tab | H13: Previously settled claims subsequently reopened. Rate × avg cost
B15: Total Reserve by Product (linked from product tabs)
B16: Product | C16: Total Reserve (£) | D16: Product Type | E16: Key Reserve Component | H16: SP1 Note
B17: PMI | C17: ='🏥 PMI'!C80 -> 34595296 | D17: Short-term | E17: UPR + AURR + IBNR + O/S + IBNER + Reopened | H17: S2.2: UPR retrospective; AURR prospective top-up where premiums inadequate
B18: CI | C18: ='🛡️ CI'!C58 -> 6.3394895e+08 | D18: Long-term | E18: Policy Reserve + IBNR + O/S + IBNER + Reopened | H18: S2.1: IBNR can be large – late notification increasingly common
B19: IP | C19: ='💼 IP'!C56 -> -6771875.4 | D19: Long-term | E19: Policy Reserve + Active Claims + IBNR + IBNER + Reopened | H19: S2.1: Active claims (disabled life reserve) uses continuance table; deferred period key to IBNR
B20: LTCI | C20: ='🏡 LTCI'!C56 -> 2906718.5 | D20: Long-term | E20: Policy Reserve + Active Claims + IBNR + IBNER + Reopened | H20: S2.1: Longest-tailed product; very sensitive to discount rate & recovery assumptions
B21: GRAND TOTAL — ALL PRODUCTS | C21: =SUM(C17:C20) -> 6.6467909e+08
B23: SP1 Ch.21 S1: Purpose of Reserves & Impact on Assumptions
B24: PUBLISHED ACCOUNTS: Best estimate or slightly prudent. True & fair view. | SOLVENCY SUPERVISION: Most prudent – or best estimate + explicit risk margin. | INTERNAL MGMT: Best estimate – realistic financial condition. | PREMIUM RATING: Best estimate ± small prudence margin. | M&A VALUATION: Near best estimate (optimistic for seller, prudent for buyer).
B25: INVESTMENT STRATEGY: Best estimate – match assets to liabilities. | REINSURANCE: Best estimate – realistic view of reinsurance needs. | The choice of basis above changes the assumptions on discount rate, claim frequency, recovery rates, inflation – NOT the model structure.
